Workbook

Sheet Instructions
A1: Insert Data taken from T-Visor Into Sheets "Speed" and "Odometer".
A2: To access data from T-Visor:
A3: Naviagate to: Tools > Diagnostics > Trends > Open Tree View
A4: When in Tree View: AvlServer > AVLS > "Odometer" or "Speed" Right click and Add to Trend (You should only download 1 data set at a time, either Speed or Odometer to then enter it into this spreadsheet)
A5: New Chart configuration will have the time and date range, choose 30 mins of the data you wish to view using either Date range or interval.
A6: Actions: + New chart
A7: At the top right of the new chart hover over actions and Export Data - this will send an email to your email address.
A8: Once the excel spreadsheet is in your email. Open it and copy and paste the data into "Speed" and "Odometer" respectively and the speed graph should automatically update with your desired result.

Sheet Extended Graph

Sheet Speed
A1: Time | B1: M's
A2: 45701.281 | B2: 0.53611111
A3: 45701.281 | B3: 0.81944444
A4: 45701.281 | B4: 1.3833333
A5: 45701.281 | B5: 1.8888889
A6: 45701.281 | B6: 2.2666667
A7: 45701.281 | B7: 2.8222222
A8: 45701.281 | B8: 3.1
A9: 45701.281 | B9: 3.325
A10: 45701.281 | B10: 3.4722222
A11: 45701.281 | B11: 3.4138889
A12: 45701.281 | B12: 3.3777778
A13: 45701.281 | B13: 3.4083333
... A1818: 45391.726 | B1818: 0

Sheet Odometer
A1: Time | B1: Odometer
A2: 45701.281 | B2: 428749898
A3: 45701.281 | B3: 428749899
A4: 45701.281 | B4: 428749901
A5: 45701.281 | B5: 428749904
A6: 45701.281 | B6: 428749907
A7: 45701.281 | B7: 428749910
A8: 45701.281 | B8: 428749914
A9: 45701.281 | B9: 428749917
A10: 45701.281 | B10: 428749920
A11: 45701.281 | B11: 428749921
A12: 45701.281 | B12: 428749924
A13: 45701.281 | B13: 428749927
... A1605: 45395.871 | B1605: 0

Sheet Speed reference
A1: Distance | B1: Speed Limit | C1: Reference
A2: 0 | B2: 15 | C2: ='[1]NB LRV Data'!E1 -> ALG
A3: 6.1 | B3: 15 | C3: ='[1]NB LRV Data'!E2 -> 15km / ALG Finish
A4: 46.94 | B4: 15 | C4: ='[1]NB LRV Data'!E3 -> I27 Start
A5: 92.82 | B5: 15
A6: 92.83 | B6: 40 | C6: ='[1]NB LRV Data'!E4 -> 40km / I27 Finish
A7: 192.32 | B7: 40
A8: 192.33 | B8: 30 | C8: ='[1]NB LRV Data'!E5 -> 30km / I26 Start
A9: 251.09 | B9: 30
A10: 251.1 | B10: 50 | C10: ='[1]NB LRV Data'!E6 -> 50km / I26 Finish
A11: 428.4 | B11: 50 | C11: ='[1]NB LRV Data'!E7 -> Midblock Crossing
A12: 500.81 | B12: 50
A13: 500.82 | B13: 40 | C13: ='[1]NB LRV Data'!E8 -> 40km / I25 Start
A14: 552.8 | B14: 40
A15: 552.81 | B15: 30 | C15: ='[1]NB LRV Data'!E9 -> ELA Start / I25 Finish
A16: 593.83 | B16: 30
A17: 593.84 | B17: 60 | C17: ='[1]NB LRV Data'!E10 -> 60km / ELA Finish
A18: 768.42 | B18: 60
A19: 768.43 | B19: 40 | C19: ='[1]NB LRV Data'!E11 -> 40km
A20: 805.23 | B20: 40 | C20: ='[1]NB LRV Data'!E12 -> I24 Start
A21: 859.45 | B21: 40 | C21: ='[1]NB LRV Data'!E13 -> I24 Finish
A22: 906.35 | B22: 40
A23: 906.36 | B23: 60 | C23: ='[1]NB LRV Data'!E14 -> 60km
A24: 1001.24 | B24: 60 | C24: ='[1]NB LRV Data'!E15 -> Midblock Crossing
A25: 1115.65 | B25: 60 | C25: ='[1]NB LRV Data'!E16 -> Midblock Crossing
A26: 1214.3 | B26: 60
A27: 1214.31 | B27: 50 | C27: ='[1]NB LRV Data'!E17 -> 50km
A28: 1259.68 | B28: 50 | C28: ='[1]NB LRV Data'!E18 -> I23 Start
A29: 1325.03 | B29: 50
A30: 1325.04 | B30: 30 | C30: ='[1]NB LRV Data'!E19 -> IPA Start / I23 Finish
A31: 1361.76 | B31: 30
A32: 1361.77 | B32: 60 | C32: ='[1]NB LRV Data'!E20 -> 60km / IPA Finish
A33: 1550.95 | B33: 60 | C33: ='[1]NB LRV Data'!E21 -> Midblock Crossing
A34: 1864.21 | B34: 60
A35: 1864.22 | B35: 50 | C35: ='[1]NB LRV Data'!E22 -> 50km
A36: 1900.34 | B36: 50 | C36: ='[1]NB LRV Data'!E23 -> I22 Start
A37: 1969.22 | B37: 50
A38: 1969.23 | B38: 30 | C38: ='[1]NB LRV Data'!E24 -> MCR Start / I22 Finish
A39: 2008.69 | B39: 30
A40: 2008.7 | B40: 60 | C40: ='[1]NB LRV Data'!E25 -> 60km / MCR Finish
...

Sheet Intersections
A1: Distance | B1: Speed Limit | C1: Reference
A2: ='[1]NB LRV Data'!D3 -> 46.94 | B2: 15 | C2: ='[1]NB LRV Data'!E3 -> I27 Start
A4: ='[1]NB LRV Data'!D5 -> 192.33 | B4: 30 | C4: ='[1]NB LRV Data'!E5 -> 30km / I26 Start
A6: ='[1]NB LRV Data'!D8 -> 500.82 | B6: 40 | C6: ='[1]NB LRV Data'!E8 -> 40km / I25 Start
A8: ='[1]NB LRV Data'!D12 -> 805.23 | B8: 40 | C8: ='[1]NB LRV Data'!E12 -> I24 Start
A10: ='[1]NB LRV Data'!D18 -> 1259.68 | B10: 50 | C10: ='[1]NB LRV Data'!E18 -> I23 Start
A12: ='[1]NB LRV Data'!D23 -> 1900.34 | B12: 50 | C12: ='[1]NB LRV Data'!E23 -> I22 Start
A14: ='[1]NB LRV Data'!D30 -> 2687.71 | B14: 40 | C14: ='[1]NB LRV Data'!E30 -> I21 Start
A16: ='[1]NB LRV Data'!D33 -> 3021 | B16: 25 | C16: ='[1]NB LRV Data'!E33 -> I19 Start
A18: ='[1]NB LRV Data'!D38 -> 3281.01 | B18: 40 | C18: ='[1]NB LRV Data'!E38 -> I18 Start
A20: ='[1]NB LRV Data'!D43 -> 3732 | B20: 50 | C20: ='[1]NB LRV Data'!E43 -> 50km / SWN Finish / I17 Start
A22: ='[1]NB LRV Data'!D47 -> 4206.8 | B22: 50 | C22: ='[1]NB LRV Data'!E47 -> I16 Start
A24: ='[1]NB LRV Data'!D50 -> 4966.28 | B24: 50 | C24: ='[1]NB LRV Data'!E50 -> I15 Start
A26: ='[1]NB LRV Data'!D55 -> 5237.84 | B26: 20 | C26: ='[1]NB LRV Data'!E55 -> 20km / I14 Start
A28: ='[1]NB LRV Data'!D58 -> 5522.48 | B28: 50 | C28: ='[1]NB LRV Data'!E58 -> 50km / I13 Start
A30: ='[1]NB LRV Data'!D62 -> 6008.12 | B30: 30 | C30: ='[1]NB LRV Data'!E62 -> 30km / I12 Start
A32: ='[1]NB LRV Data'!D66 -> 6602.78 | B32: 25 | C32: ='[1]NB LRV Data'!E66 -> 25km / I11 Start
A34: ='[1]NB LRV Data'!D69 -> 6764.3 | B34: 50 | C34: ='[1]NB LRV Data'!E69 -> 50km SFD Finish / I10 Start
A36: ='[1]NB LRV Data'!D73 -> 7353.01 | B36: 50 | C36: ='[1]NB LRV Data'!E73 -> I9 Start
A38: ='[1]NB LRV Data'!D77 -> 7771.63 | B38: 50 | C38: ='[1]NB LRV Data'!E77 -> I8 Start
A40: ='[1]NB LRV Data'!D80 -> 8191.91 | B40: 30 | C40: ='[1]NB LRV Data'!E80 -> WSN Finish / I7 Start
A42: ='[1]NB LRV Data'!D86 -> 9064.38 | B42: 40 | C42: ='[1]NB LRV Data'!E86 -> I6 Start
A44: ='[1]NB LRV Data'!D93 -> 9858.38 | B44: 50 | C44: ='[1]NB LRV Data'!E93 -> I5 Start
A46: ='[1]NB LRV Data'!D98 -> 10600.86 | B46: 50 | C46: ='[1]NB LRV Data'!E98 -> I4 Start
A48: ='[1]NB LRV Data'!D102 -> 11068.25 | B48: 50 | C48: ='[1]NB LRV Data'!E102 -> I3 Start
A50: ='[1]NB LRV Data'!D107 -> 11501.51 | B50: 50 | C50: ='[1]NB LRV Data'!E107 -> I2 Start
A52: ='[1]NB LRV Data'!D109 -> 11713.56 | B52: 20 | C52: ='[1]NB LRV Data'!E109 -> I01 Start

Sheet Stops
A1: Distance | B1: Speed Limit | C1: Reference
A2: ='[1]NB LRV Data'!D1 -> 0 | B2: 15 | C2: ='[1]NB LRV Data'!E1 -> ALG
A3: ='[1]NB LRV Data'!D2 -> 6.1 | B3: 15 | C3: ALG
A5: ='[1]NB LRV Data'!D9 -> 552.81 | B5: 30 | C5: ELA
A6: 593.83 | B6: 30 | C6: ELA
A8: ='[1]NB LRV Data'!D19 -> 1325.04 | B8: 30 | C8: IPA
A9: 1361.76 | B9: 30 | C9: IPA
A11: ='[1]NB LRV Data'!D24 -> 1969.23 | B11: 30 | C11: MCR
A12: 2008.69 | B12: 30 | C12: MCR
A14: ='[1]NB LRV Data'!D34 -> 3041.26 | B14: 25 | C14: DKN
A15: ='[1]NB LRV Data'!D35 -> 3075.81 | B15: 25 | C15: DKN
A17: ='[1]NB LRV Data'!D42 -> 3692.03 | B17: 30 | C17: SWN
A18: 3731.99 | B18: 30 | C18: SWN
A20: ='[1]NB LRV Data'!D51 -> 5032.36 | B20: 30 | C20: PLP
A21: ='[1]NB LRV Data'!D52 -> 5068.47 | B21: 30 | C21: PLP
A23: ='[1]NB LRV Data'!D60 -> 5926.53 | B23: 30 | C23: EPC
A24: ='[1]NB LRV Data'!D61 -> 5960.85 | B24: 30 | C24: EPC
A26: ='[1]NB LRV Data'!D68 -> 6724.69 | B26: 25 | C26: SFD
A27: 6764.29 | B27: 25 | C27: SFD
A29: ='[1]NB LRV Data'!D79 -> 8154.02 | B29: 30 | C29: WSN
A30: ='[1]NB LRV Data'!D80 -> 8191.91 | B30: 30 | C30: WSN
A32: ='[1]NB LRV Data'!D88 -> 9130.09 | B32: 30 | C32: NLR
A33: ='[1]NB LRV Data'!D89 -> 9164.81 | B33: 30 | C33: NLR
A35: ='[1]NB LRV Data'!D94 -> 9915.42 | B35: 30 | C35: MPN
A36: 9956.91 | B36: 30 | C36: MPN
A38: ='[1]NB LRV Data'!D103 -> 11123.29 | B38: 30 | C38: MCK
A39: ='[1]NB LRV Data'!D104 -> 11160.97 | B39: 30 | C39: MCK
A41: ='[1]NB LRV Data'!D112 -> 11867.26 | B41: 15 | C41: GGN
A42: ='[1]NB LRV Data'!D113 -> 11901.05 | B42: 15 | C42: GGN

Sheet Calculations
A1: Time | B1: Time rounded (Speed) | C1: M's | D1: Time | E1: Time rounded (odo) | F1: Odometer | G1: ODO/Trip | H1: ODO total | I1: Time Overall | J1: Time rounded (Overall) | K1: ODO/Time | L1: M/S | M1: KM/s
A2: =Speed!A2 -> 45701.281 | B2: =MROUND(A2,"00:00:01") -> 45701.281 | C2: =Speed!B2 -> 0.53611111 | D2: =Odometer!A2 -> 45701.281 | E2: =MROUND(D2,"00:00:01") -> 45701.281 | F2: =Odometer!B2 -> 428749898 | G2: =IF(F3-F2<0,0,F3-F2) -> 1 | H2: =G2 -> 1 | I2: =A2 -> 45701.281 | J2: =MROUND(I2,"0:00:01") -> 45701.281 | K2: =IFERROR(INDEX($H$2:$H$2000,MATCH(J2,$E$2:$E$2000,0)),NA()) -> #N/A | L2: =INDEX($C$2:$C$2000, MATCH(I2,$A$2:$A$2000,0)) -> 0.53611111 | M2: =L2*3.6 -> 1.93
A3: =Speed!A3 -> 45701.281 | B3: =MROUND(A3,"00:00:01") -> 45701.281 | C3: =Speed!B3 -> 0.81944444 | D3: =Odometer!A3 -> 45701.281 | E3: =MROUND(D3,"00:00:01") -> 45701.281 | F3: =Odometer!B3 -> 428749899 | G3: =IF(F4-F3<0,0,F4-F3) -> 2 | H3: =SUM($G$2:G3) -> 3 | I3: =A3 -> 45701.281 | J3: =MROUND(I3,"0:00:01") -> 45701.281 | K3: =IFERROR(INDEX($H$2:$H$2000,MATCH(J3,$E$2:$E$2000,0)),NA()) -> #N/A | L3: =INDEX($C$2:$C$2000, MATCH(I3,$A$2:$A$2000,0)) -> 0.53611111 | M3: =L3*3.6 -> 1.93
A4: =Speed!A4 -> 45701.281 | B4: =MROUND(A4,"00:00:01") -> 45701.281 | C4: =Speed!B4 -> 1.3833333 | D4: =Odometer!A4 -> 45701.281 | E4: =MROUND(D4,"00:00:01") -> 45701.281 | F4: =Odometer!B4 -> 428749901 | G4: =IF(F5-F4<0,0,F5-F4) -> 3 | H4: =SUM($G$2:G4) -> 6 | I4: =A4 -> 45701.281 | J4: =MROUND(I4,"0:00:01") -> 45701.281 | K4: =IFERROR(INDEX($H$2:$H$2000,MATCH(J4,$E$2:$E$2000,0)),NA()) -> 1 | L4: =INDEX($C$2:$C$2000, MATCH(I4,$A$2:$A$2000,0)) -> 1.3833333 | M4: =L4*3.6 -> 4.98
A5: =Speed!A5 -> 45701.281 | B5: =MROUND(A5,"00:00:01") -> 45701.281 | C5: =Speed!B5 -> 1.8888889 | D5: =Odometer!A5 -> 45701.281 | E5: =MROUND(D5,"00:00:01") -> 45701.281 | F5: =Odometer!B5 -> 428749904 | G5: =IF(F6-F5<0,0,F6-F5) -> 3 | H5: =SUM($G$2:G5) -> 9 | I5: =A5 -> 45701.281 | J5: =MROUND(I5,"0:00:01") -> 45701.281 | K5: =IFERROR(INDEX($H$2:$H$2000,MATCH(J5,$E$2:$E$2000,0)),NA()) -> #N/A | L5: =INDEX($C$2:$C$2000, MATCH(I5,$A$2:$A$2000,0)) -> 1.8888889 | M5: =L5*3.6 -> 6.8
A6: =Speed!A6 -> 45701.281 | B6: =MROUND(A6,"00:00:01") -> 45701.281 | C6: =Speed!B6 -> 2.2666667 | D6: =Odometer!A6 -> 45701.281 | E6: =MROUND(D6,"00:00:01") -> 45701.281 | F6: =Odometer!B6 -> 428749907 | G6: =IF(F7-F6<0,0,F7-F6) -> 3 | H6: =SUM($G$2:G6) -> 12 | I6: =A6 -> 45701.281 | J6: =MROUND(I6,"0:00:01") -> 45701.281 | K6: =IFERROR(INDEX($H$2:$H$2000,MATCH(J6,$E$2:$E$2000,0)),NA()) -> 6 | L6: =INDEX($C$2:$C$2000, MATCH(I6,$A$2:$A$2000,0)) -> 2.2666667 | M6: =L6*3.6 -> 8.16
A7: =Speed!A7 -> 45701.281 | B7: =MROUND(A7,"00:00:01") -> 45701.281 | C7: =Speed!B7 -> 2.8222222 | D7: =Odometer!A7 -> 45701.281 | E7: =MROUND(D7,"00:00:01") -> 45701.281 | F7: =Odometer!B7 -> 428749910 | G7: =IF(F8-F7<0,0,F8-F7) -> 4 | H7: =SUM($G$2:G7) -> 16 | I7: =A7 -> 45701.281 | J7: =MROUND(I7,"0:00:01") -> 45701.281 | K7: =IFERROR(INDEX($H$2:$H$2000,MATCH(J7,$E$2:$E$2000,0)),NA()) -> 9 | L7: =INDEX($C$2:$C$2000, MATCH(I7,$A$2:$A$2000,0)) -> 2.8222222 | M7: =L7*3.6 -> 10.16
A8: =Speed!A8 -> 45701.281 | B8: =MROUND(A8,"00:00:01") -> 45701.281 | C8: =Speed!B8 -> 3.1 | D8: =Odometer!A8 -> 45701.281 | E8: =MROUND(D8,"00:00:01") -> 45701.281 | F8: =Odometer!B8 -> 428749914 | G8: =IF(F9-F8<0,0,F9-F8) -> 3 | H8: =SUM($G$2:G8) -> 19 | I8: =A8 -> 45701.281 | J8: =MROUND(I8,"0:00:01") -> 45701.281 | K8: =IFERROR(INDEX($H$2:$H$2000,MATCH(J8,$E$2:$E$2000,0)),NA()) -> 12 | L8: =INDEX($C$2:$C$2000, MATCH(I8,$A$2:$A$2000,0)) -> 3.1 | M8: =L8*3.6 -> 11.16
A9: =Speed!A9 -> 45701.281 | B9: =MROUND(A9,"00:00:01") -> 45701.281 | C9: =Speed!B9 -> 3.325 | D9: =Odometer!A9 -> 45701.281 | E9: =MROUND(D9,"00:00:01") -> 45701.281 | F9: =Odometer!B9 -> 428749917 | G9: =IF(F10-F9<0,0,F10-F9) -> 3 | H9: =SUM($G$2:G9) -> 22 | I9: =A9 -> 45701.281 | J9: =MROUND(I9,"0:00:01") -> 45701.281 | K9: =IFERROR(INDEX($H$2:$H$2000,MATCH(J9,$E$2:$E$2000,0)),NA()) -> 12 | L9: =INDEX($C$2:$C$2000, MATCH(I9,$A$2:$A$2000,0)) -> 3.1 | M9: =L9*3.6 -> 11.16
A10: =Speed!A10 -> 45701.281 | B10: =MROUND(A10,"00:00:01") -> 45701.281 | C10: =Speed!B10 -> 3.4722222 | D10: =Odometer!A10 -> 45701.281 | E10: =MROUND(D10,"00:00:01") -> 45701.281 | F10: =Odometer!B10 -> 428749920 | G10: =IF(F11-F10<0,0,F11-F10) -> 1 | H10: =SUM($G$2:G10) -> 23 | I10: =A10 -> 45701.281 | J10: =MROUND(I10,"0:00:01") -> 45701.281 | K10: =IFERROR(INDEX($H$2:$H$2000,MATCH(J10,$E$2:$E$2000,0)),NA()) -> 19 | L10: =INDEX($C$2:$C$2000, MATCH(I10,$A$2:$A$2000,0)) -> 3.4722222 | M10: =L10*3.6 -> 12.5
A11: =Speed!A11 -> 45701.281 | B11: =MROUND(A11,"00:00:01") -> 45701.281 | C11: =Speed!B11 -> 3.4138889 | D11: =Odometer!A11 -> 45701.281 | E11: =MROUND(D11,"00:00:01") -> 45701.281 | F11: =Odometer!B11 -> 428749921 | G11: =IF(F12-F11<0,0,F12-F11) -> 3 | H11: =SUM($G$2:G11) -> 26 | I11: =A11 -> 45701.281 | J11: =MROUND(I11,"0:00:01") -> 45701.281 | K11: =IFERROR(INDEX($H$2:$H$2000,MATCH(J11,$E$2:$E$2000,0)),NA()) -> 22 | L11: =INDEX($C$2:$C$2000, MATCH(I11,$A$2:$A$2000,0)) -> 3.4138889 | M11: =L11*3.6 -> 12.29
A12: =Speed!A12 -> 45701.281 | B12: =MROUND(A12,"00:00:01") -> 45701.281 | C12: =Speed!B12 -> 3.3777778 | D12: =Odometer!A12 -> 45701.281 | E12: =MROUND(D12,"00:00:01") -> 45701.281 | F12: =Odometer!B12 -> 428749924 | G12: =IF(F13-F12<0,0,F13-F12) -> 3 | H12: =SUM($G$2:G12) -> 29 | I12: =A12 -> 45701.281 | J12: =MROUND(I12,"0:00:01") -> 45701.281 | K12: =IFERROR(INDEX($H$2:$H$2000,MATCH(J12,$E$2:$E$2000,0)),NA()) -> 26 | L12: =INDEX($C$2:$C$2000, MATCH(I12,$A$2:$A$2000,0)) -> 3.3777778 | M12: =L12*3.6 -> 12.16
A13: =Speed!A13 -> 45701.281 | B13: =MROUND(A13,"00:00:01") -> 45701.281 | C13: =Speed!B13 -> 3.4083333 | D13: =Odometer!A13 -> 45701.281 | E13: =MROUND(D13,"00:00:01") -> 45701.281 | F13: =Odometer!B13 -> 428749927 | G13: =IF(F14-F13<0,0,F14-F13) -> 4 | H13: =SUM($G$2:G13) -> 33 | I13: =A13 -> 45701.281 | J13: =MROUND(I13,"0:00:01") -> 45701.281 | K13: =IFERROR(INDEX($H$2:$H$2000,MATCH(J13,$E$2:$E$2000,0)),NA()) -> 29 | L13: =INDEX($C$2:$C$2000, MATCH(I13,$A$2:$A$2000,0)) -> 3.4083333 | M13: =L13*3.6 -> 12.27
A14: =Speed!A14 -> 45701.281 | B14: =MROUND(A14,"00:00:01") -> 45701.281 | C14: =Speed!B14 -> 3.6472222 | D14: =Odometer!A14 -> 45701.281 | E14: =MROUND(D14,"00:00:01") -> 45701.281 | F14: =Odometer!B14 -> 428749931 | G14: =IF(F15-F14<0,0,F15-F14) -> 4 | H14: =SUM($G$2:G14) -> 37 | I14: =A14 -> 45701.281 | J14: =MROUND(I14,"0:00:01") -> 45701.281 | K14: =IFERROR(INDEX($H$2:$H$2000,MATCH(J14,$E$2:$E$2000,0)),NA()) -> 33 | L14: =INDEX($C$2:$C$2000, MATCH(I14,$A$2:$A$2000,0)) -> 3.6472222 | M14: =L14*3.6 -> 13.13
... A2000: =Speed!A2000 -> 0 | B2000: =MROUND(A2000,"00:00:01") -> 0 | C2000: =Speed!B2000 -> 0 | D2000: =Odometer!A2000 -> 0 | E2000: =MROUND(D2000,"00:00:01") -> 0 | F2000: =Odometer!B2000 -> 0 | G2000: =IF(F2001-F2000<0,0,F2001-F2000) -> 0 | H2000: =SUM($G$2:G2000) -> 11920 | I2000: =A2000 -> 0 | J2000: =MROUND(I2000,"0:00:01") -> 0 | K2000: =IFERROR(INDEX($H$2:$H$2000,MATCH(J2000,$E$2:$E$2000,0)),NA()) -> 11920 | L2000: =INDEX($C$2:$C$2000, MATCH(I2000,$A$2:$A$2000,0)) -> 0 | M2000: =L2000*3.6 -> 0
G2001: =IF(F2002-F2001<0,0,F2002-F2001) -> 0 | H2001: =SUM($G$2:G2001) -> 11920
